<?xml version="1.0" ?>
<robot name="robot_scara" xmlns:xacro="http://ros.org/wiki/xacro">

<!--<robot name="robot_scara">-->

    <link name="base_link">
        <visual>
            <origin xyz="0.0 0.0 0.10" rpy="0.0 0.0 0.0" />
            <geometry>
                <box size="0.15 0.10 0.20" />
            </geometry>
            <material name="gray">
                <color rgba="0.1 0.1 0.1 1.0" />
            </material>
        </visual>

        <collision>
            <origin xyz="0.0 0.0 0.10" rpy="0.0 0.0 0.0" />
            <geometry>
                <box size="0.15 0.10 0.20" />
            </geometry>
        </collision>

        <inertial>
            <mass value="1.0" />
            <origin xyz="0.0 0.0 0.0" rpy="0.0 0.0 0.0" />
            <inertia ixx="1.0" ixy="0.0" ixz="0.0" iyy="1.0" iyz="0.0" izz="1.0" />
        </inertial>
    </link>

    <link name="link_1">
        <visual>
            <origin xyz="0.25 0.0 0.025" rpy="0.0 0.0 0.0" />
            <geometry>
                <box size="0.5 0.05 0.05" />
            </geometry>
            <material name="red">
                <color rgba="1.0 0.0 0.0 1.0" />
            </material>
        </visual>

        <collision>
            <origin xyz="0.25 0.0 0.025" rpy="0.0 0.0 0.0" />
            <geometry>
                <box size="0.5 0.05 0.05" />
            </geometry>
        </collision>

        <inertial>
            <mass value="1.0" />
            <origin xyz="0.0 0.0 0.0" rpy="0.0 0.0 0.0" />
            <inertia ixx="1.0" ixy="0.0" ixz="0.0" iyy="1.0" iyz="0.0" izz="1.0" />
        </inertial>
    </link>

    <joint name="ink_1_joint" type="revolute">
        <parent link="base_link" />
        <child link="link_1" />
        <axis xyz="0 0 1" />
        <limit lower="-1.57" upper="1.57" velocity="1" 
            effort="1000" />
        <origin xyz="0.0 0.0 0.2" rpy="0 0 0" />
    </joint>

    <link name="link_2">
        <visual>
            <origin xyz="0.25 0.0 0.025" rpy="0.0 0.0 0.0" />
            <geometry>
                <box size="0.5 0.05 0.05" />
            </geometry>
            <material name="green">
                <color rgba="0.0 1.0 0.0 1.0" />
            </material>
        </visual>

        <collision>
            <origin xyz="0.25 0.0 0.025" rpy="0.0 0.0 0.0" />
            <geometry>
                <box size="0.5 0.05 0.05" />
            </geometry>
        </collision>

        <inertial>
            <mass value="1.0" />
            <origin xyz="0.0 0.0 0.0" rpy="0.0 0.0 0.0" />
            <inertia ixx="1.0" ixy="0.0" ixz="0.0" iyy="1.0" iyz="0.0" izz="1.0" />
        </inertial>
    </link>

    <joint name="link_2_joint" type="revolute">
        <parent link="link_1" />
        <child link="link_2" />
        <axis xyz="0 0 1" />
        <limit lower="-1.57" upper="1.57" velocity="1" 
            effort="1000" />
        <origin xyz="0.5 0.0 0.05" rpy="0 0 0" />
    </joint>    

    <link name="link_3">
        <visual>
            <origin xyz="0.25 0.0 0.025" rpy="0.0 0.0 0.0" />
            <geometry>
                <box size="0.5 0.05 0.05" />
            </geometry>
            <material name="blue">
                <color rgba="0.0 0.0 1.0 1.0" />
            </material>
        </visual>

        <collision>
            <origin xyz="0.25 0.0 0.025" rpy="0.0 0.0 0.0" />
            <geometry>
                <box size="0.5 0.05 0.05" />
            </geometry>
        </collision>

        <inertial>
            <mass value="1.0" />
            <origin xyz="0.0 0.0 0.0" rpy="0.0 0.0 0.0" />
            <inertia ixx="1.0" ixy="0.0" ixz="0.0" iyy="1.0" iyz="0.0" izz="1.0" />
        </inertial>
    </link>

    <joint name="link_3_joint" type="revolute">
        <parent link="link_2" />
        <child link="link_3" />
        <axis xyz="0 0 1" />
        <limit lower="-1.57" upper="1.57" velocity="1" 
            effort="1000" />
        <origin xyz="0.5 0.0 0.05" rpy="0 0 0" />
    </joint>    

</robot>